{"uid":"4b4757e66a1912dae1a509f688f20b0f","name":"categories","children":[{"name":"Test defects","children":[{"name":"The following error originated from your test code, not from Cypress.\n                \n                  > Cannot call `cy.allure()` outside a running test.\n                \n                This usually happens when you accidentally write commands outside an `it(...)` test.\n                \n                If that is the case, just move these commands inside an `it(...)` test.\n                \n                Check your test file for errors.\n                \n                When Cypress detects uncaught errors originating from your test code it will automatically fail the current test.\n                \n                Cypress could not associate this error to any specific test.\n                \n                We dynamically generated a new test to display this failure.\n                \n                https://on.cypress.io/cannot-execute-commands-outside-test","children":[{"name":"An uncaught error was detected outside of a test","uid":"495a0734d839c2e9","parentUid":"f40cd9a28e0b6a9b09789cfff7ca17b2","status":"broken","time":{"start":1665866070640,"stop":1665866070764,"duration":124},"flaky":false,"newFailed":false,"newPassed":false,"newBroken":false,"retriesCount":0,"retriesStatusChange":false,"parameters":[]}],"uid":"f40cd9a28e0b6a9b09789cfff7ca17b2"}],"uid":"bdbf199525818fae7a8651db9eafe741"}]}